Workbook

Sheet CLAIMS
B1: Date | C1: Customer | D1: Model | E1: Chassis | F1: Part No. | G1: Description | H1: Qty | I1: Lot affected | J1: Reason Code | K1: CATEGORY | L1: RCA | M1: MMO PO | N1: EST. COST | O1: CORRECT COST | P1: Claim/Order Date | Q1: OEM Response | R1: OEM Remarks | S1: OEM Packing date | T1: Sea/ flight Detail | U1: ETA-Kenya | V1: ETA-AVA | W1: Receiving Date | X1: Qty | Y1: Process aging | Z1: Rework date | AA1: Status | AB1: Remark
A2: 1 | B2: 45121 | C2: Seal | D2: P440 | E2: 4042392, 4042395, 4042399,4042401,4042403,4042404, 4042405, 4042406, 4042407 | F2: 2673171 | G2: Grommet Lamp Guard | H2: 36 | I2: Ket013/23 | J2: Manufacturer Error | K2: KDQR | M2: N/A | P2: 45181 | Q2: Accepted | W2: 45306 | X2: 1 | Y2: =IF(P2="","",IF(W2="",TODAY()-P2,W2-P2)) -> 125
A3: 2 | B3: 45131 | C3: Toyota | D3: Hilux | E3: N/A | F3: 56101-0kp40 | G3: Glass sub assy, windsheld | H3: 1 | I3: FY010 | J3: Manufacturer Error | K3: KDQR | M3: N/A | P3: 45181 | W3: 45155 | X3: 1 | Y3: =IF(P3="","",IF(W3="",TODAY()-P3,W3-P3)) -> -26
A4: 3 | B4: 45131 | C4: Toyota | D4: Hilux | E4: N/A | F4: 16711-0l180 | G4: Shroud Fan | H4: 1 | I4: FX007 | J4: Wrong Shipment | K4: KDQR | M4: N/A | P4: 45181 | W4: 45155 | X4: 5 | Y4: =IF(P4="","",IF(W4="",TODAY()-P4,W4-P4)) -> -26
A5: 4 | B5: 45131 | C5: Toyota | D5: Hilux | E5: N/A | F5: 67914-kk020 | G5: Plate Door Scuff, LH | H5: 5 | I5: FX007 | J5: Short Shipment | K5: KDQR | M5: N/A | P5: 45181 | W5: 45131 | Y5: =IF(P5="","",IF(W5="",TODAY()-P5,W5-P5)) -> -50
A6: 5 | B6: 45131 | C6: Toyota | D6: Hilux | E6: N/A | F6: 90159-T0037 | G6: Screw w/washer | H6: 60 | I6: Fw6,8,9, Fy4,5,7 | J6: Short Shipment | K6: KDQR | M6: N/A | P6: 45188 | W6: 45173 | X6: 500 | Y6: =IF(P6="","",IF(W6="",TODAY()-P6,W6-P6)) -> -15
A7: 6 | B7: 45131 | C7: Toyota | D7: Hilux | E7: N/A | F7: 90119-T0126 | G7: Bolt W/Washer | H7: 500 | I7: Fw6,8,9, Fy4,5,7 | J7: Short Shipment | K7: KDQR | M7: N/A | P7: 45191 | W7: 45426 | X7: 4 | Y7: =IF(P7="","",IF(W7="",TODAY()-P7,W7-P7)) -> 235 | AB7: Bal 116
A8: 7 | B8: 45131 | C8: Toyota | D8: Hilux | E8: N/A | F8: 90119-T0141 | G8: Bolt W/Washer | H8: 120 | I8: Fw6,8,9, Fy4,5,7 | J8: Manufacturer Error | K8: KDQR | M8: N/A | P8: 45191 | W8: =VLOOKUP(#REF!, 'STORE ITEMS'!$C$2:F$1000, 4, FALSE) -> #REF! | Y8: =IF(P8="","",IF(W8="",TODAY()-P8,W8-P8)) -> #REF!
A9: 8 | B9: 45131 | C9: Toyota | D9: Hilux | E9: N/A | F9: 55522-0k010 | G9: f786 | H9: 2 | I9: Fw009 | J9: Wrong Shipment | K9: KDQR | M9: N/A | P9: 45191 | Y9: =IF(P9="","",IF(W9="",TODAY()-P9,W9-P9)) -> 395
A10: 9 | B10: 45125 | C10: Toyota | D10: Hilux | E10: N/A | F10: 55406-kk150 co | G10: Panelsub- Assy Instr lwctr | H10: 5 | I10: Fw008 | J10: Wrong Shipment | K10: KDQR | M10: N/A | P10: 45244 | W10: 45308 | X10: 16 | Y10: =IF(P10="","",IF(W10="",TODAY()-P10,W10-P10)) -> 64
A11: 10 | B11: 45237 | C11: Scm | D11: 9016 | E11: JL0904 | F11: F3205710 | G11: CONTROL ROD | H11: 16 | I11: LK115 | J11: Short Shipment | K11: KDQR | M11: N/A | P11: 45191 | W11: 45561 | Y11: =IF(P11="","",IF(W11="",TODAY()-P11,W11-P11)) -> 370
A12: 11 | B12: 45128 | C12: Seal | D12: Scania | E12: 4043325 | F12: 2773351 | G12: Reignforcement Bracket | H12: 2 | I12: Keb002/23 | J12: Line Damage | K12: MMO | M12: PCM-000033 | P12: 45133 | W12: 45257 | X12: 1 | Y12: =IF(P12="","",IF(W12="",TODAY()-P12,W12-P12)) -> 124
A13: 12 | B13: 45133 | C13: Toyota | D13: VDJ | E13: 7740302 | F13: 51741-60060 | G13: BRACKET, RR BODY MOUNTING, NO.1 | H13: 1 | I13: GF067 | J13: Line Damage | K13: MMO | M13: PCM-000033 | P13: 45133 | W13: 45257 | X13: 1 | Y13: =IF(P13="","",IF(W13="",TODAY()-P13,W13-P13)) -> 124
A14: 13 | B14: 45133 | C14: Toyota | D14: VDJ | E14: 7740301 | F14: 51744-60020 | G14: cROSSMEMBER SUB-ASSY, FRAME, RR | H14: 1 | I14: GF067 | J14: Line Damage | K14: MMO | M14: PCM-000033 | P14: 45133 | W14: 45257 | X14: 1 | Y14: =IF(P14="","",IF(W14="",TODAY()-P14,W14-P14)) -> 124
A15: 14 | B15: 45133 | C15: Toyota | D15: VDJ | E15: 7740300 | F15: 51701-60070 | G15: BRACKET SUB-ASSY, CAB FR MOUNTING, RH | H15: 1 | I15: GF067 | J15: Line Damage | K15: MMO | M15: PCM-000033 | P15: 45133 | W15: 45257 | X15: 2 | Y15: =IF(P15="","",IF(W15="",TODAY()-P15,W15-P15)) -> 124
A16: 15 | B16: 45133 | C16: Toyota | D16: VDJ | E16: 7740301 | F16: 51763-60010 | G16: BRACKET, BODY SUPPORT, NO.6 | H16: 1 | I16: GF067 | J16: Line Damage | K16: MMO | M16: PCM-000033 | P16: 45133 | W16: 45257 | X16: 1 | Y16: =IF(P16="","",IF(W16="",TODAY()-P16,W16-P16)) -> 124
A17: 16 | B17: 45133 | C17: Toyota | D17: VDJ | E17: 7740301 | F17: 51209-60081 | G17: CROSSMEMBER SUB-ASSY, FRAME, RR | H17: 1 | I17: GF067 | J17: Line Damage | K17: MMO | P17: 45167 | W17: 45257 | X17: 2 | Y17: =IF(P17="","",IF(W17="",TODAY()-P17,W17-P17)) -> 90
A18: 17 | B18: 45133 | C18: Toyota | D18: Hiace | E18: N/A | F18: 41991-60061 | G18: Differential Lock System Operation | H18: 1 | I18: N/A | J18: Wrong Shipment | K18: KDQR | M18: N/A | P18: 45244 | W18: 45308 | X18: 16 | Y18: =IF(P18="","",IF(W18="",TODAY()-P18,W18-P18)) -> 64
A19: 18 | B19: 45237 | C19: Scm | D19: 9016 | E19: JL0904 | F19: F1700900 | G19: SA OF BALL JOINT | H19: 16 | I19: LK115 | J19: Manufacturer Error | K19: KDQR | M19: N/A | P19: 45244 | W19: 45308 | X19: 16 | Y19: =IF(P19="","",IF(W19="",TODAY()-P19,W19-P19)) -> 64
A20: 19 | B20: 45237 | C20: Scm | D20: 9016 | E20: JL0907 | F20: B2034307 | G20: S/A BALL JOINT | H20: 16 | I20: LK115 | J20: Manufacturer Error | K20: KDQR | M20: N/A | P20: 45244 | W20: 45308 | X20: 1 | Y20: =IF(P20="","",IF(W20="",TODAY()-P20,W20-P20)) -> 64
A21: 20 | B21: 45238 | C21: Scm | D21: 9016 | E21: JL0913 | F21: B1211616 | G21: DAT TANK | H21: 1 | I21: LK115 | J21: Short Shipment | K21: KDQR | M21: N/A | P21: 45205 | W21: 45147 | X21: 12 | Y21: =IF(P21="","",IF(W21="",TODAY()-P21,W21-P21)) -> -58
A22: 21 | B22: 45128 | C22: Seal | D22: Scania | E22: N/A | F22: 816102 | G22: Press Screw M12 | H22: 6 | I22: Keb1 | J22: Short Shipment | K22: KDQR | M22: N/A | P22: 45205 | W22: 45377 | X22: 1 | Y22: =IF(P22="","",IF(W22="",TODAY()-P22,W22-P22)) -> 172
A23: 22 | B23: 45138 | C23: Toyota | D23: Hilux | E23: 5634441/5634354 | F23: 69090-0k080 | G23: HANDLE ASSY BACK OUTSIDE | H23: 2 | I23: EZ2 | J23: Line Loss | K23: MMO | M23: PCM-000036 | P23: 45205 | W23: 45184 | X23: 16 | Y23: =IF(P23="","",IF(W23="",TODAY()-P23,W23-P23)) -> -21
A24: 23 | B24: 45138 | C24: Toyota | D24: Hilux | E24: 5634441 | F24: 67861-0k151 | G24: WEATHERSTRIP FR DOOR RH | H24: 1 | I24: EZ5 | J24: Line Loss | K24: MMO | M24: PCM-000036 | N24: 20.84 | P24: 45222 | W24: 45180 | X24: 1 | Y24: =IF(P24="","",IF(W24="",TODAY()-P24,W24-P24)) -> -42
A25: 24 | B25: 45138 | C25: Toyota | D25: Hilux | E25: 5634441 | F25: 52110-0k0580-B1 | G25: BUMPER ASSY FR | H25: 1 | I25: EZ5 | J25: Line Loss | K25: MMO | M25: PCM-000036 | P25: 45142 | W25: 45184 | X25: 16 | Y25: =IF(P25="","",IF(W25="",TODAY()-P25,W25-P25)) -> 42
A26: 25 | B26: 45138 | C26: Toyota | D26: Hilux | E26: 5634441 | F26: 52163-0K040 | G26: PLATE RR BUMBER RH | H26: 3 | I26: EZ5 | J26: Line Loss | K26: MMO | M26: PCM-000036 | N26: 14.37 | P26: 45142 | W26: 45180 | X26: 4 | Y26: =IF(P26="","",IF(W26="",TODAY()-P26,W26-P26)) -> 38
A27: 26 | B27: 45138 | C27: Toyota | D27: Hilux | E27: 5634441 | F27: 71003-0K851-C1 | G27: FR SEAT SET,LH | H27: 1 | I27: EZ5 | J27: Line Loss | K27: MMO | M27: PCM-000036 | N27: 1114.13 | P27: 45142 | W27: 45180 | X27: 1 | Y27: =IF(P27="","",IF(W27="",TODAY()-P27,W27-P27)) -> 38
A28: 27 | B28: 45138 | C28: Toyota | D28: Hilux | E28: 6234618 | F28: 67491-KK020 | G28: GARNISH FR DOOR RH | H28: 1 | I28: DK6 | J28: Line Loss | K28: MMO | M28: PCM-000037 | N28: 3.69 | P28: 45142 | W28: 44988 | Y28: =IF(P28="","",IF(W28="",TODAY()-P28,W28-P28)) -> -154
A29: 28 | B29: 45138 | C29: Toyota | D29: Hilux | E29: 6234618 | F29: 74250-0K200 | G29: ARMREST ASSY DOOR RH | H29: 1 | I29: DK6 | J29: Line Loss | K29: MMO | M29: PCM-000037 | N29: 18.12 | P29: 45142 | Y29: =IF(P29="","",IF(W29="",TODAY()-P29,W29-P29)) -> 444
A30: 29 | B30: 45138 | C30: Toyota | D30: Hilux | E30: 6234618 | F30: 53100-0KK00 | G30: GRILLE ASSY RADIATOR | H30: 1 | I30: DK6 | J30: Line Loss | K30: MMO | M30: PCM-000037 | N30: 353.43 | P30: 45142 | W30: 45184 | Y30: =IF(P30="","",IF(W30="",TODAY()-P30,W30-P30)) -> 42
A31: 30 | B31: 45138 | C31: Toyota | D31: Hilux | E31: 6234618 | F31: 71003-0KA52 | G31: FR SEAT SET,LH | H31: 1 | I31: DK6 | J31: Line Loss | K31: MMO | M31: PCM-000037 | P31: 45142 | W31: 45180 | X31: 1 | Y31: =IF(P31="","",IF(W31="",TODAY()-P31,W31-P31)) -> 38
A32: 31 | B32: 45138 | C32: Toyota | D32: Hilux | E32: 6234618 | F32: 53117-0K130 | G32: RETAINER, RADIATOR GRILLE, NO.1 | H32: 4 | I32: DK6 | J32: Line Loss | K32: MMO | M32: PCM-000037 | N32: 25.04 | P32: 45142 | Y32: =IF(P32="","",IF(W32="",TODAY()-P32,W32-P32)) -> 444
A33: 32 | B33: 45138 | C33: Toyota | D33: Hilux | E33: 6234618 | F33: 69284-0K040 | G33: PLUG, DOOR INSIDE HANDLE BEZEL, LH | H33: 1 | I33: DK6 | J33: Line Loss | K33: MMO | M33: PCM-000037 | P33: 45142 | Y33: =IF(P33="","",IF(W33="",TODAY()-P33,W33-P33)) -> 444
A34: 33 | B34: 45138 | C34: Toyota | D34: Hilux | E34: 5633893 | F34: 90333-01009 | G34: PLUG PLATE | H34: 4 | I34: CZ3 | J34: Line Loss | K34: MMO | M34: PCM-000025 | P34: 45142 | W34: 45098 | X34: 200 | Y34: =IF(P34="","",IF(W34="",TODAY()-P34,W34-P34)) -> -44
A35: 34 | B35: 45138 | C35: Toyota | D35: Hilux | E35: 5762959 | G35: HOOK BODY ASSY RR(WHITE) | H35: 1 | I35: DL13 | J35: Line Loss | K35: MMO | M35: PCM-000038 | P35: 45142 | Y35: =IF(P35="","",IF(W35="",TODAY()-P35,W35-P35)) -> 444
A36: 35 | B36: 45138 | C36: Toyota | D36: Hilux | E36: 5762959 | F36: 53117-0K050 | G36: RETAINER RADIATOR GRILLE NO.1 | H36: 2 | I36: DL13 | J36: Line Loss | K36: MMO | M36: PCM-000038 | N36: 14.74 | P36: 45142 | W36: 45180 | X36: 2 | Y36: =IF(P36="","",IF(W36="",TODAY()-P36,W36-P36)) -> 38
A37: 36 | B37: 45138 | C37: Toyota | D37: Hilux | E37: 5762959 | F37: 53115-0K090 | G37: BRACKET RADIATOR GRILLE | H37: 1 | I37: DL13 | J37: Line Loss | K37: MMO | M37: PCM-000038 | N37: 1.21 | P37: 45142 | W37: 45184 | X37: 1 | Y37: =IF(P37="","",IF(W37="",TODAY()-P37,W37-P37)) -> 42
A38: 37 | B38: 45138 | C38: Toyota | D38: Hilux | E38: 5762959/5763027/5633941 | G38: REAR AXLE GROMMET | H38: 20 | I38: DL13,FY1,DC14 | J38: Short Shipment | K38: KDQR | M38: N/A | P38: 45142 | Y38: =IF(P38="","",IF(W38="",TODAY()-P38,W38-P38)) -> 444
A39: 38 | B39: 45138 | C39: Toyota | D39: Hilux | E39: 5763027 | G39: FUEL FLAP GROMMET | H39: 4 | I39: FY1 | J39: Line Loss | K39: MMO | M39: PCM-000042 | P39: 45142 | Y39: =IF(P39="","",IF(W39="",TODAY()-P39,W39-P39)) -> 444
A40: 39 | B40: 45138 | C40: Toyota | D40: Hilux | E40: 5634354 | F40: 90119-T0220 | G40: BOLT W/WASHER | H40: 4 | I40: EZ2 | J40: Line Loss | K40: MMO | M40: PCM-000043 | N40: 0.13 | P40: 45142 | W40: 45155 | Y40: =IF(P40="","",IF(W40="",TODAY()-P40,W40-P40)) -> 13
...

Sheet ROBBING LIST
A1: SNO | B1: DATE | C1: CUSTOMER | D1: MODEL | E1: PART NO | F1: PART NAME | G1: QTY | H1: REASON CODE | I1: LOT AFFECTED | J1: LOT ROBBED | L1: CLAIM STATUS
A2: 1 | B2: 19/01/2024 | C2: FUSO | D2: FJ2528/ 2523C | E2: A4008809714 | F2: ZB BRACKET/ LOWER ASSY RH | G2: 6 | K2: =VLOOKUP(E2,CLAIMS!F:K,5,FALSE) -> #N/A | L2: NOT CLAIMED
B3: 19/01/2024 | C3: FUSO | D3: FJ2528/ 2523C | E3: A4004310115 | F3: LU AIR DRIER | G3: 2 | K3: =VLOOKUP(E3,CLAIMS!F:K,5,FALSE) -> Short Shipment
B4: 19/01/2024 | C4: FUSO | D4: FJ2528/ 2523C | E4: A0039976689 | F4: LU COUPLING PLUG | G4: 6 | K4: =VLOOKUP(E4,CLAIMS!F:K,5,FALSE) -> Short Shipment
B5: 19/01/2024 | C5: FUSO | D5: FJ2528/ 2523C | E5: N000912008206 | F5: CAP BOLT M8 X 45 | G5: 24 | K5: =VLOOKUP(E5,CLAIMS!F:K,5,FALSE) -> Short Shipment
B6: 19/01/2024 | C6: FUSO | D6: FJ2528/ 2523C | E6: A4006603830 | F6: ZB SUPPORTING TUBE | G6: 1 | K6: =VLOOKUP(E6,CLAIMS!F:K,5,FALSE) -> Wrong Shipment
B7: 19/01/2024 | C7: FUSO | D7: FJ2528/ 2523C | E7: N0000000003250 | F7: WASHER ISO | G7: 320 | K7: =VLOOKUP(E7,CLAIMS!F:K,5,FALSE) -> #N/A | L7: NOT CLAIMED
B8: 19/01/2024 | C8: FUSO | D8: FJ2528/ 2523C | E8: A4005406609 | F8: ZB ELECTRICAL WIRING HARNESS | G8: 6 | K8: =VLOOKUP(E8,CLAIMS!F:K,5,FALSE) -> Not Supplied
B9: 19/01/2024 | C9: FUSO | D9: FJ2528/ 2523C | E9: A400524940 | F9: ZB BRACKET | G9: 24 | K9: =VLOOKUP(E9,CLAIMS!F:K,5,FALSE) -> #N/A | L9: NOT CLAIMED
B10: 19/01/2024 | C10: FUSO | D10: FJ2528/ 2523C | E10: A4005451907 | F10: LU ROCKER SWITCH | G10: 6 | K10: =VLOOKUP(E10,CLAIMS!F:K,5,FALSE) -> #N/A | L10: NOT CLAIMED
B11: 19/01/2024 | C11: FUSO | D11: FJ2528/ 2523C | E11: A4006800108 | F11: ZB COVER RH | G11: 1 | K11: =VLOOKUP(E11,CLAIMS!F:K,5,FALSE) -> Short Shipment
B12: 19/01/2024 | C12: FUSO | D12: FJ2528/ 2523C | E12: A4008172814 | F12: MODEL IDENTIFICATION FJ | G12: 1 | K12: =VLOOKUP(E12,CLAIMS!F:K,5,FALSE) -> #N/A | L12: NOT CLAIMED
B13: 19/01/2024 | C13: FUSO | D13: FJ2528/ 2523C | E13: A0009906350 | F13: NUT | G13: 24 | K13: =VLOOKUP(E13,CLAIMS!F:K,5,FALSE) -> #N/A | L13: NOT CLAIMED
B14: 19/01/2024 | C14: FUSO | D14: FJ2528/ 2523C | E14: A0009903978 | F14: CONNECTION SLEEVE | G14: 6 | K14: =VLOOKUP(E14,CLAIMS!F:K,5,FALSE) -> #N/A | L14: NOT CLAIMED
B15: 19/01/2024 | C15: FUSO | D15: FJ2528/ 2523C | E15: N000000001935 | F15: SCREW | G15: 24 | K15: =VLOOKUP(E15,CLAIMS!F:K,5,FALSE) -> Short Shipment
B16: 19/01/2024 | C16: FUSO | D16: FJ2528/ 2523C | E16: A4007600759 | F16: LU DOOR HANDLE/HDT LH | G16: 1 | K16: =VLOOKUP(E16,CLAIMS!F:K,5,FALSE) -> #N/A | L16: NOT CLAIMED
B17: 19/01/2024 | C17: FUSO | D17: FJ2528/ 2523C | E17: A4008100419 | F17: LU KERB MIRROR/ HDT | G17: 1 | K17: =VLOOKUP(E17,CLAIMS!F:K,5,FALSE) -> #N/A | L17: NOT CLAIMED
B18: 19/01/2024 | C18: FUSO | D18: FJ2528/ 2523C | E18: A4006900150A7 | F18: HEADLINER RR/S/L | G18: 1 | K18: =VLOOKUP(E18,CLAIMS!F:K,5,FALSE) -> #N/A | L18: NOT CLAIMED
B19: 19/01/2024 | C19: FUSO | D19: FJ2528/ 2523C | E19: A4008201439 | F19: HEADLAMP RH | G19: 1 | K19: =VLOOKUP(E19,CLAIMS!F:K,5,FALSE) -> #N/A | L19: NOT CLAIMED
B20: 25...26/03/2024 | C20: FUSO | D20: FM 657 | E20: MC859640 | F20: KEY SET | G20: 8 | J20: 331/332 | K20: =VLOOKUP(E20,CLAIMS!F:K,5,FALSE) -> Line Damage
B21: 25...26/03/2025 | C21: FUSO | D21: FM 657 | E21: MK510347 | F21: MIRROR ROOM | G21: 1 | J21: 332 | K21: =VLOOKUP(E21,CLAIMS!F:K,5,FALSE) -> #N/A | L21: NOT CLAIMED
B22: 25...26/03/2026 | C22: FUSO | D22: FM 657 | E22: MC857723 | F22: SENSOR SPEED | G22: 1 | J22: 332 | K22: =VLOOKUP(E22,CLAIMS!F:K,5,FALSE) -> Line Damage
B23: 25...26/03/2027 | C23: FUSO | D23: FM 657 | E23: MC0000056 | F23: CHAIN | G23: 4 | J23: 332 | K23: =VLOOKUP(E23,CLAIMS!F:K,5,FALSE) -> #N/A | L23: NOT CLAIMED
B24: 25...26/03/2028 | C24: FUSO | D24: FM 657 | E24: MK421275 | F24: BUZZER WARNING | G24: 8 | J24: 331/332 | K24: =VLOOKUP(E24,CLAIMS!F:K,5,FALSE) -> Line Loss
B25: 25...26/03/2029 | C25: FUSO | D25: FM 657 | E25: MH039716 | F25: CONNECTOR | G25: 7 | J25: 332 | K25: =VLOOKUP(E25,CLAIMS!F:K,5,FALSE) -> #N/A | L25: NOT CLAIMED
B26: 25...26/03/2030 | C26: FUSO | D26: FM 657 | E26: MA155254 | F26: CLIP | G26: 4 | J26: 332 | K26: =VLOOKUP(E26,CLAIMS!F:K,5,FALSE) -> #N/A | L26: NOT CLAIMED
B27: 25...26/03/2031 | C27: FUSO | D27: FM 657 | E27: MC420079 | F27: PIN SHACKLE | G27: 20 | J27: 332 | K27: =VLOOKUP(E27,CLAIMS!F:K,5,FALSE) -> #N/A | L27: NOT CLAIMED
B28: 25...26/03/2032 | C28: FUSO | D28: FM 657 | E28: MC928534 | F28: CLIP | G28: 2 | J28: 332 | K28: =VLOOKUP(E28,CLAIMS!F:K,5,FALSE) -> #N/A | L28: NOT CLAIMED
B29: 25...26/03/2033 | C29: FUSO | D29: FM 657 | E29: MC923837 | F29: HOOD METER | G29: 4 | J29: 332 | K29: =VLOOKUP(E29,CLAIMS!F:K,5,FALSE) -> Wrong Shipment
B30: 25...26/03/2034 | C30: FUSO | D30: FM 657 | E30: MC932101 | F30: BLOWER ASSY | G30: 3 | J30: 332 | K30: =VLOOKUP(E30,CLAIMS!F:K,5,FALSE) -> #N/A | L30: NOT CLAIMED
B31: 25...26/03/2035 | C31: FUSO | D31: FM 657 | E31: ML249166 | F31: TRIM BACK | G31: 4 | J31: 332 | K31: =VLOOKUP(E31,CLAIMS!F:K,5,FALSE) -> Pack Damage
B32: 25...26/03/2036 | C32: FUSO | D32: FM 657 | E32: MC645114 | F32: HOSE AIR INTAKE | G32: 4 | J32: 332 | K32: =VLOOKUP(E32,CLAIMS!F:K,5,FALSE) -> #N/A | L32: NOT CLAIMED
B33: 25...26/03/2037 | C33: FUSO | D33: FM 657 | E33: MF140287 | F33: BOLT FLANGE | G33: 14 | J33: 332 | K33: =VLOOKUP(E33,CLAIMS!F:K,5,FALSE) -> #N/A | L33: NOT CLAIMED
B34: 25...26/03/2038 | C34: FUSO | D34: FM 657 | E34: MC887439 | F34: TUNER AM RADIO | G34: 2 | J34: 332 | K34: =VLOOKUP(E34,CLAIMS!F:K,5,FALSE) -> Line Damage
B35: 25...26/03/2039 | C35: FUSO | D35: FM 657 | E35: MC645513 | F35: COVER SHAFT FRONT | G35: 1 | J35: 332 | K35: =VLOOKUP(E35,CLAIMS!F:K,5,FALSE) -> #N/A | L35: NOT CLAIMED
B36: 25...26/03/2040 | C36: FUSO | D36: FM 657 | E36: ML273158 | F36: TRIM RR SIDE | G36: 4 | J36: 332 | K36: =VLOOKUP(E36,CLAIMS!F:K,5,FALSE) -> Wrong Shipment
B37: 25...26/03/2041 | C37: FUSO | D37: FM 657 | E37: MK510557 | F37: LAMP PERSONAL | G37: 1 | J37: 332 | K37: =VLOOKUP(E37,CLAIMS!F:K,5,FALSE) -> Manufacturer Error
B38: 25...26/03/2042 | C38: FUSO | D38: FM 657 | E38: MC021036 | F38: CLIP | G38: 4 | J38: 332 | K38: =VLOOKUP(E38,CLAIMS!F:K,5,FALSE) -> #N/A | L38: NOT CLAIMED
B39: 25...26/03/2043 | C39: FUSO | D39: FM 657 | E39: ML241750 | F39: CABLE IDLE CONTROL(CLIP) | G39: 1 | J39: 332 | K39: =VLOOKUP(E39,CLAIMS!F:K,5,FALSE) -> #N/A | L39: NOT CLAIMED
B40: 25...26/03/2044 | C40: FUSO | D40: FM 657 | E40: MH00483 | F40: BOLT REAMER | G40: 32 | J40: 332 | K40: =VLOOKUP(E40,CLAIMS!F:K,5,FALSE) -> #N/A | L40: NOT CLAIMED
...

Sheet STORE ITEMS
A1: CUSTOMER | B1: MODEL | C1: PART NO | D1: DESCRIPTION | E1: QTY | F1: DATE RECEIVED | G1: QTY ISSUED | H1: DATE ISSUED | I1: ISSUED TO | J1: REMARKS | K1: STATUS
A2: Scm | B2: ASHOK | C2: FH300161 | D2: LOGO | E2: 5 | F2: 45026 | K2: RECEIVED | P2: =VLOOKUP(C2, CLAIMS!A1:K2000, 4, FALSE) | S2: =VLOOKUP(O2, A2:M2000, 4, FALSE) -> #N/A
A3: SCM | C3: ME 445615 | D3: PUMP GENERAL ASSY SUPPLY | E3: 1 | F3: 45038 | K3: RECEIVED | M3: ALL ITEMS ISSUED | S3: =VLOOKUP(C3, A3:M2001, 4, FALSE) -> #N/A
A4: Scm | C4: ME 132100Y | D4: DISK ASSY DRIVING | E4: 1 | F4: 45038 | K4: RECEIVED | S4: =VLOOKUP(C4, A4:M2002, 4, FALSE) -> #N/A
A5: Scm | C5: MC 040495 | D5: NUT FLANGE | E5: 1 | F5: 45038 | K5: RECEIVED | M5: NOT ALL ITEMS ISSUED
A6: Scm | C6: MF 434105 | D6: NUT FLANGE | E6: 3 | F6: 45038 | K6: RECEIVED
A7: Scm | C7: MS 146022 | D7: BOLT FLANGE | E7: 1 | F7: 45038 | K7: RECEIVED
A8: Scm | C8: MS 146006 | D8: BOLT FLANGE | E8: 1 | F8: 45038 | K8: RECEIVED
A9: Scm | C9: MH 001884 | D9: BOLT HEX SOCKET | E9: 3 | F9: 45038 | K9: RECEIVED
A10: Scm | C10: ME 306511 | D10: COVER TIMING GEAR | E10: 1 | F10: 45038 | K10: RECEIVED
A11: Scm | C11: ME 305844 | D11: BLOCK COUPLING | E11: 1 | F11: 45038 | K11: RECEIVED
A12: Scm | C12: MH 035547 | D12: O-RING | E12: 1 | F12: 45038 | K12: RECEIVED
A13: Scm | C13: MH 035224 | D13: O-RING | E13: 1 | F13: 45038 | K13: RECEIVED
A14: Scm | C14: ML 258531 | D14: PAD FLOOR | E14: 48 | F14: 45132 | G14: 2,36 | H14: 26 JUL 23,4/8/23 | I14: VOPSY,PETER | K14: ISSUED
A15: Scm | C15: A 4308260043 | D15: DIRECTION INDICTOR | E15: 12 | F15: 45132 | K15: RECEIVED
A16: Scm | C16: A 4308260143 | D16: BLINK LAMP | E16: 12 | F16: 45132 | K16: RECEIVED
A17: Scm | C17: MB 288654 | D17: FLANGE NUT SELF LOCK | E17: 1 | F17: 45089 | K17: RECEIVED
A18: Scm | C18: MR 161694 | D18: CLIP | E18: 1 | F18: 45089 | K18: RECEIVED
A19: Scm | C19: MR 569334 | D19: CLIP | E19: 1 | F19: 45089 | K19: RECEIVED
A20: Scm | C20: MU 001912 | D20: FLANGE NUT SELF LOCK | E20: 6 | F20: 45089 | K20: RECEIVED
A21: Scm | C21: MU 488006 | D21: CLIP | E21: 4 | F21: 45089 | K21: RECEIVED
A22: Scm | C22: MR 510882 | D22: CLIP | E22: 1 | F22: 45089 | K22: RECEIVED
A23: Scm | C23: MF 472086 | D23: PIN SLIP(4*35) | E23: 2 | F23: 45089 | K23: RECEIVED
A24: Scm | C24: MF 472069 | D24: PIN SLIP(3*35) | E24: 3 | F24: 45089 | K24: RECEIVED
A25: Scm | C25: MF 472085 | D25: PIN SLIP(4*30) | E25: 1 | F25: 45089 | K25: RECEIVED
A26: Scm | C26: MB 895413 | D26: CLIP | E26: 2 | F26: 45089 | K26: RECEIVED
... A28: Scm | C28: MR 462285 | D28: STOPER GLASS | E28: 2 | F28: 45089 | K28: RECEIVED
A29: Scm | C29: ME298716 | D29: RADIATOR | E29: 1 | F29: 45132 | G29: 1 | H29: 6/OCT/23 | I29: EMANUEL BAYA | K29: ISSUED
A30: Scm | C30: MK323353 | D30: GRILLE | E30: 2 | F30: 45132 | K30: RECEIVED
A31: Scm | C31: MC923839 | D31: COVER LOWER | E31: 1 | F31: 45132 | K31: RECEIVED
A32: Scm | B32: FM657L | C32: MK513092 | D32: SUNVISOR | E32: 1 | F32: 45132 | G32: 1 | H32: 5/OCT/23 | I32: BAKARI | K32: ISSUED
A33: Scm | C33: MK484299 | D33: INSULATOR | E33: 1 | F33: 45132 | J33: =SUBTOTAL(109,J3:J32) -> 0 | K33: RECEIVED
A34: Scm | B34: FM657L | C34: MC932101 | D34: BLOWER ASSY | E34: 1 | F34: 45132 | H34: 45205 | I34: BAYA | K34: ISSUED
A35: Scm | C35: ML324236 | D35: BLOWER ASSY | E35: 3 | F35: 45132 | K35: RECEIVED
A36: Scm | C36: MC934640 | D36: HEATER UNIT | E36: 1 | F36: 45132 | G36: 1 | H36: 45205 | I36: BAYA | K36: ISSUED
A37: Scm | C37: MC091460 | D37: INTEGRAL | E37: 1 | F37: 45132 | G37: 1 | H37: 45205 | I37: BAYA | K37: ISSUED
A38: Scm | C38: ME290700 | D38: MUFFLER | E38: 1 | F38: 45132 | G38: 1 | H38: 45205 | I38: BAYA | K38: ISSUED
A39: Scm | C39: 326333000 | D39: WASHER | E39: 8 | F39: 45132 | K39: RECEIVED
A40: Scm | C40: 326332000 | D40: WASHER | E40: 8 | F40: 45132 | K40: RECEIVED
A41: Scm | B41: FM657L | C41: MC037694 | D41: NUT | E41: 1 | F41: 45132 | G41: 1 | H41: 6/OCT/23 | I41: BAYA | K41: ISSUED
...

Sheet LIST
A2: CFAO | B2: Not Supplied | J2: ECOMET | M2: CLAIMED
A3: TATA | B3: Line Loss | E3: MMO | F3: Scm | G3: Late Order | H3: Accepted | J3: VDJ | K3: N/A | L3: ISSUED | M3: STORE
A4: SIMBA DELUX | B4: Line Damage | E4: KDQR | F4: Toyota | G4: Incorrect Data | H4: Rejected | J4: Hiace | K4: DONE | L4: RECEIVED | M4: NOT CLAIMED
A5: SIMBA | B5: Short Shipment | F5: Seal | G5: Lack of Evidence | H5: N/A | J5: Hilux | K5: NOT DONE | L5: BEING CONSUMED
A6: NELION | B6: Pack Damage | F6: Tata | J6: FEA51
A7: SCANIA | B7: Manufacturer Error | E7: =IFERROR(INDEX(D:D, MATCH(#REF!,B:B,0)), "") | F7: Nelion | J7: FECX
B8: Wrong Shipment | F8: Auto Industries | J8: Fortuner
B9: BOM Error | F9: ISM | J9: CT2518
B10: Backlog | F10: CAG | J10: Partner
B11: EOL | F11: TVS | J11: FI EV
B12: Rework | F12: Aspire | J12: FJ2523C
B13: Paint Rec | F13: Deluxe | J13: FJ1623R
B14: Mulfunction | J14: Haulage
J15: FI1217R
J16: Scania P360
J17: Scania P380
J18: Scania P440
J19: 1216
J20: 2516
J21: FE84CE
J22: FE85CH
J23: FE85CG
J24: FM657L
J25: FN627R
J26: Tata T.9
J27: Piaggio
J28: FJ2528C
J29: FJ2528R
J30: Scania G500
J31: Tata Daewoo
F32: OPEN | J32: FN62FU
F33: CLOSED | J33: FM65FL
J34: Marcopolo
J35: L200
D36: FRONT BUMPER BRKT RH | E36: 1 | F36: 374 | G36: Wrong Shipment | J36: Scania F360
C37: F1104300 | D37: FRONT WIND SHIELD GLASS | E37: 3 | F37: LK107 | J37: Scania
C38: F2203000 | D38: EXH BR SWITCH (X2206000) | E38: 16 | F38: LK109 | J38: Phoenix
C39: B5583111 | D39: ARM ASSY DOOR CHEC | E39: 2 | F39: AK0025 | J39: Scania P410
C40: B5583112 | D40: ARM ASSYDOOR CHECK | E40: 2 | F40: AK0025 | J40: BOSS
C41: FHT00190 | D41: 220L FUEL TANK CAP | E41: 1 | F41: LK111 | J41: U2523
...
